Workbook

Sheet BP 2026
B1: ACTUAL + FORECAST __Company name______________________________
C3: BP | D3: BP | E3: BP | F3: BP | G3: BP | H3: BP | I3: BP | J3: BP | K3: BP | L3: BP | M3: BP | N3: BP | O3: BP
B4: Cuenta de Resultados | C4: 2026 | D4: 2026 | E4: 2026 | F4: 2026 | G4: 2026 | H4: 2026 | I4: 2026 | J4: 2026 | K4: 2026 | L4: 2026 | M4: 2026 | N4: 2026 | O4: 2026
C5: Enero | D5: Febrero | E5: Marzo | F5: Abril | G5: Mayo | H5: Junio | I5: Julio | J5: Agosto | K5: Septiembre | L5: Octubre | M5: Noviembre | N5: Diciembre | O5: Total
B7: REVENUE | O7: =+SUM(C7:N7) -> 0
B8: % Growth | C8: =IFERROR((C7/B7)-1,"na") -> na | D8: =IFERROR((D7/C7)-1,"na") -> na | E8: =IFERROR((E7/D7)-1,"na") -> na | F8: =IFERROR((F7/E7)-1,"na") -> na | G8: =IFERROR((G7/F7)-1,"na") -> na | H8: =IFERROR((H7/G7)-1,"na") -> na | I8: =IFERROR((I7/H7)-1,"na") -> na | J8: =IFERROR((J7/I7)-1,"na") -> na | ... N8: =IFERROR((N7/M7)-1,"na") -> na
B9: COGS | O9: =+SUM(C9:N9) -> 0
B10: GROSS MARGIN | C10: =C7+C9 -> 0 | D10: =D7+D9 -> 0 | E10: =E7+E9 -> 0 | F10: =F7+F9 -> 0 | G10: =G7+G9 -> 0 | H10: =H7+H9 -> 0 | I10: =I7+I9 -> 0 | J10: =J7+J9 -> 0 | ... O10: =O7+O9 -> 0
B11: as % of Revenue | C11: =IFERROR(C10/C7,"na") -> na | D11: =IFERROR(D10/D7,"na") -> na | E11: =IFERROR(E10/E7,"na") -> na | F11: =IFERROR(F10/F7,"na") -> na | G11: =IFERROR(G10/G7,"na") -> na | H11: =IFERROR(H10/H7,"na") -> na | I11: =IFERROR(I10/I7,"na") -> na | J11: =IFERROR(J10/J7,"na") -> na | ... O11: =IFERROR(O10/O7,"na") -> na
B12: DIRECT LABOR COST | O12: =+SUM(C12:N12) -> 0
B13: HEADCOUNT | O13: =+SUM(C13:N13) -> 0
B14: CONTRIBUTION MARGIN | C14: =C7+C9+C12 -> 0 | D14: =D7+D9+D12 -> 0 | E14: =E7+E9+E12 -> 0 | F14: =F7+F9+F12 -> 0 | G14: =G7+G9+G12 -> 0 | H14: =H7+H9+H12 -> 0 | I14: =I7+I9+I12 -> 0 | J14: =J7+J9+J12 -> 0 | ... O14: =O7+O9+O12 -> 0
B15: as % of Revenue | C15: =IFERROR(C14/C7,"na") -> na | D15: =IFERROR(D14/D7,"na") -> na | E15: =IFERROR(E14/E7,"na") -> na | F15: =IFERROR(F14/F7,"na") -> na | G15: =IFERROR(G14/G7,"na") -> na | H15: =IFERROR(H14/H7,"na") -> na | I15: =IFERROR(I14/I7,"na") -> na | J15: =IFERROR(J14/J7,"na") -> na | ... N15: =IFERROR(N14/N7,"na") -> na | O15: =IFERROR(O14/$O$7,"na") -> na
B16: TOTAL OPERATING EXPENSES (OPEX) | C16: =+C18+C19 -> 0 | D16: =+D18+D19 -> 0 | E16: =+E18+E19 -> 0 | F16: =+F18+F19 -> 0 | G16: =+G18+G19 -> 0 | H16: =+H18+H19 -> 0 | I16: =+I18+I19 -> 0 | J16: =+J18+J19 -> 0 | ... O16: =+O18+O19 -> 0
B17: as % of Revenue | C17: =IFERROR(C16/C7,"na") -> na | D17: =IFERROR(D16/D7,"na") -> na | E17: =IFERROR(E16/E7,"na") -> na | F17: =IFERROR(F16/F7,"na") -> na | G17: =IFERROR(G16/G7,"na") -> na | H17: =IFERROR(H16/H7,"na") -> na | I17: =IFERROR(I16/I7,"na") -> na | J17: =IFERROR(J16/J7,"na") -> na | ... N17: =IFERROR(N16/N7,"na") -> na | O17: =IFERROR(O16/$O$7,"na") -> na
B18: MKT (agencias, paid, fees amazon,etc) | O18: =+SUM(C18:N18) -> 0
B19: Other OPEX | O19: =+SUM(C19:N19) -> 0
B20: EBITDA | C20: =C14+C16 -> 0 | D20: =D14+D16 -> 0 | E20: =E14+E16 -> 0 | F20: =F14+F16 -> 0 | G20: =G14+G16 -> 0 | H20: =H14+H16 -> 0 | I20: =I14+I16 -> 0 | J20: =J14+J16 -> 0 | ... O20: =O14+O16 -> 0
B21: as % of Revenue | C21: =IFERROR(C20/C7,"na") -> na | D21: =IFERROR(D20/D7,"na") -> na | E21: =IFERROR(E20/E7,"na") -> na | F21: =IFERROR(F20/F7,"na") -> na | G21: =IFERROR(G20/G7,"na") -> na | H21: =IFERROR(H20/H7,"na") -> na | I21: =IFERROR(I20/I7,"na") -> na | J21: =IFERROR(J20/J7,"na") -> na | ... O21: =IFERROR(O20/O7,"na") -> na
B22: Amortizaciones
B23: EBIT | C23: =C20+C22 -> 0 | D23: =D20+D22 -> 0 | E23: =E20+E22 -> 0 | F23: =F20+F22 -> 0 | G23: =G20+G22 -> 0 | H23: =H20+H22 -> 0 | I23: =I20+I22 -> 0 | J23: =J20+J22 -> 0 | ... O23: =O20+O22 -> 0
B24: as % of Revenue | C24: =IFERROR(C23/C7,"na") -> na | D24: =IFERROR(D23/D7,"na") -> na | E24: =IFERROR(E23/E7,"na") -> na | F24: =IFERROR(F23/F7,"na") -> na | G24: =IFERROR(G23/G7,"na") -> na | H24: =IFERROR(H23/H7,"na") -> na | I24: =IFERROR(I23/I7,"na") -> na | J24: =IFERROR(J23/J7,"na") -> na | ... O24: =IFERROR(O23/O7,"na") -> na
B25: Restd. Financiero
B26: Impuesto sociedades
B27: NET INCOME | C27: =C25+C26 -> 0 | D27: =D25+D26 -> 0 | E27: =E25+E26 -> 0 | F27: =F25+F26 -> 0 | G27: =G25+G26 -> 0 | H27: =H25+H26 -> 0 | I27: =I25+I26 -> 0 | J27: =J25+J26 -> 0 | ... O27: =O25+O26 -> 0
C29: BP | D29: BP | E29: BP | F29: BP | G29: BP | H29: BP | I29: BP | J29: BP | K29: BP | L29: BP | M29: BP | N29: BP
B30: Cash Flow | C30: 2026 | D30: 2026 | E30: 2026 | F30: 2026 | G30: 2026 | H30: 2026 | I30: 2026 | J30: 2026 | K30: 2026 | L30: 2026 | M30: 2026 | N30: 2026
C31: Enero | D31: Febrero | E31: Marzo | F31: Abril | G31: Mayo | H31: Junio | I31: Julio | J31: Agosto | K31: Septiembre | L31: Octubre | M31: Noviembre | N31: Diciembre
B32: CASH-INS | C32: =+SUM(C33:C35) -> 0 | D32: =+SUM(D33:D35) -> 0 | E32: =+SUM(E33:E35) -> 0 | F32: =+F7 -> 0 | G32: =+G7 -> 0 | H32: =+H7 -> 0 | I32: =+I7 -> 0 | J32: =+J7 -> 0 | K32: =+K7 -> 0 | L32: =+L7 -> 0 | M32: =+M7 -> 0 | N32: =+N7 -> 0
B33: Cash position BoP
B34: Revenues
B35: APORTACION K
B36: CASH-OUT | C36: =+SUM(C37:C40) -> 0 | D36: =+SUM(D37:D40) -> 0 | E36: =+SUM(E37:E40) -> 0 | F36: =+SUM(F37:F40) -> 0 | G36: =+SUM(G37:G40) -> 0 | H36: =+SUM(H37:H40) -> 0 | I36: =+SUM(I37:I40) -> 0 | J36: =+SUM(J37:J40) -> 0 | ... N36: =+SUM(N37:N40) -> 0
B37: COGS
B38: Direct Labor
B39: Total OPEX
B40: PROFIT SHARING
B41: CAPEX
B42: TOTAL CASH-OUTS + CAPEX | C42: =+C36+C41 -> 0 | D42: =+D36+D41 -> 0 | E42: =+E36+E41 -> 0 | F42: =+F36+F41 -> 0 | G42: =+G36+G41 -> 0 | H42: =+H36+H41 -> 0 | I42: =+I36+I41 -> 0 | J42: =+J36+J41 -> 0 | ... N42: =+N36+N41 -> 0
B43: Costes financieros
...

Sheet Template
B2: ACTUAL + FORECAST | C2: [Company Name]
C4: ACTUAL | D4: ACTUAL | E4: ACTUAL | F4: FORECAST | G4: FORECAST | H4: FORECAST | I4: FORECAST | J4: FORECAST | K4: FORECAST | L4: FORECAST | M4: FORECAST | N4: FORECAST | O4: Actual+Forecast | Q4: BP
B5: Cuenta de Resultados | C5: 2026 | D5: 2026 | E5: 2026 | F5: 2026 | G5: 2026 | H5: 2026 | I5: 2026 | J5: 2026 | K5: 2026 | L5: 2026 | M5: 2026 | N5: 2026 | O5: 2026 | Q5: 2026
C6: Enero | D6: Febrero | E6: Marzo | F6: Abril | G6: Mayo | H6: Junio | I6: Julio | J6: Agosto | K6: Septiembre | L6: Octubre | M6: Noviembre | N6: Diciembre | O6: Total | Q6: Total | S6: Dif | T6: Comentarios
B8: REVENUE | O8: =+SUM(C8:N8) -> 0 | S8: =+O8-Q8 -> 0
B9: % Growth | C9: =IFERROR((C8/B8)-1,"na") -> na | D9: =IFERROR((D8/C8)-1,"na") -> na | E9: =IFERROR((E8/D8)-1,"na") -> na | F9: =IFERROR((F8/E8)-1,"na") -> na | G9: =IFERROR((G8/F8)-1,"na") -> na | H9: =IFERROR((H8/G8)-1,"na") -> na | I9: =IFERROR((I8/H8)-1,"na") -> na | J9: =IFERROR((J8/I8)-1,"na") -> na | ... N9: =IFERROR((N8/M8)-1,"na") -> na
B10: COGS | O10: =+SUM(C10:N10) -> 0 | S10: =+O10-Q10 -> 0
B11: GROSS MARGIN | C11: =C8+C10 -> 0 | D11: =D8+D10 -> 0 | E11: =E8+E10 -> 0 | F11: =F8+F10 -> 0 | G11: =G8+G10 -> 0 | H11: =H8+H10 -> 0 | I11: =I8+I10 -> 0 | J11: =J8+J10 -> 0 | ... O11: =O8+O10 -> 0 | Q11: =Q8+Q10 -> 0 | S11: =+O11-Q11 -> 0
B12: as % of Revenue | C12: =IFERROR(C11/C8,"na") -> na | D12: =IFERROR(D11/D8,"na") -> na | E12: =IFERROR(E11/E8,"na") -> na | F12: =IFERROR(F11/F8,"na") -> na | G12: =IFERROR(G11/G8,"na") -> na | H12: =IFERROR(H11/H8,"na") -> na | I12: =IFERROR(I11/I8,"na") -> na | J12: =IFERROR(J11/J8,"na") -> na | ... O12: =IFERROR(O11/O8,"na") -> na | Q12: =IFERROR(Q11/Q8,"na") -> na
B13: DIRECT LABOR COST | O13: =+SUM(C13:N13) -> 0 | S13: =+O13-Q13 -> 0
B14: HEADCOUNT | O14: =+SUM(C14:N14) -> 0
B15: CONTRIBUTION MARGIN | C15: =C8+C10+C13 -> 0 | D15: =D8+D10+D13 -> 0 | E15: =E8+E10+E13 -> 0 | F15: =F8+F10+F13 -> 0 | G15: =G8+G10+G13 -> 0 | H15: =H8+H10+H13 -> 0 | I15: =I8+I10+I13 -> 0 | J15: =J8+J10+J13 -> 0 | ... O15: =O8+O10+O13 -> 0 | Q15: =Q8+Q10+Q13 -> 0 | S15: =+O15-Q15 -> 0
B16: as % of Revenue | C16: =IFERROR(C15/C8,"na") -> na | D16: =IFERROR(D15/D8,"na") -> na | E16: =IFERROR(E15/E8,"na") -> na | F16: =IFERROR(F15/F8,"na") -> na | G16: =IFERROR(G15/G8,"na") -> na | H16: =IFERROR(H15/H8,"na") -> na | I16: =IFERROR(I15/I8,"na") -> na | J16: =IFERROR(J15/J8,"na") -> na | ... N16: =IFERROR(N15/N8,"na") -> na | O16: =IFERROR(O15/$O$8,"na") -> na | Q16: =IFERROR(Q15/Q8,"na") -> na
B17: TOTAL OPERATING EXPENSES (OPEX) | C17: =+C19+C20 -> 0 | D17: =+D19+D20 -> 0 | E17: =+E19+E20 -> 0 | F17: =+F19+F20 -> 0 | G17: =+G19+G20 -> 0 | H17: =+H19+H20 -> 0 | I17: =+I19+I20 -> 0 | J17: =+J19+J20 -> 0 | ... O17: =+O19+O20 -> 0 | S17: =+O17-Q17 -> 0
B18: as % of Revenue | C18: =IFERROR(C17/C8,"na") -> na | D18: =IFERROR(D17/D8,"na") -> na | E18: =IFERROR(E17/E8,"na") -> na | F18: =IFERROR(F17/F8,"na") -> na | G18: =IFERROR(G17/G8,"na") -> na | H18: =IFERROR(H17/H8,"na") -> na | I18: =IFERROR(I17/I8,"na") -> na | J18: =IFERROR(J17/J8,"na") -> na | ... N18: =IFERROR(N17/N8,"na") -> na | O18: =IFERROR(O17/$O$8,"na") -> na | Q18: =IFERROR(Q17/$O$8,"na") -> na
B19: MKT (agencias, paid, fees amazon,etc) | O19: =+SUM(C19:N19) -> 0 | S19: =+O19-Q19 -> 0
B20: Other OPEX | O20: =+SUM(C20:N20) -> 0 | S20: =+O20-Q20 -> 0
B21: EBITDA | C21: =C15+C17 -> 0 | D21: =D15+D17 -> 0 | E21: =E15+E17 -> 0 | F21: =F15+F17 -> 0 | G21: =G15+G17 -> 0 | H21: =H15+H17 -> 0 | I21: =I15+I17 -> 0 | J21: =J15+J17 -> 0 | ... O21: =O15+O17 -> 0 | S21: =+O21-Q21 -> 0
B22: as % of Revenue | C22: =IFERROR(C21/C8,"na") -> na | D22: =IFERROR(D21/D8,"na") -> na | E22: =IFERROR(E21/E8,"na") -> na | F22: =IFERROR(F21/F8,"na") -> na | G22: =IFERROR(G21/G8,"na") -> na | H22: =IFERROR(H21/H8,"na") -> na | I22: =IFERROR(I21/I8,"na") -> na | J22: =IFERROR(J21/J8,"na") -> na | ... O22: =IFERROR(O21/O8,"na") -> na | Q22: =IFERROR(Q21/Q8,"na") -> na
B23: Amortizaciones | S23: =+O23-Q23 -> 0
B24: EBIT | C24: =C21+C23 -> 0 | D24: =D21+D23 -> 0 | E24: =E21+E23 -> 0 | F24: =F21+F23 -> 0 | G24: =G21+G23 -> 0 | H24: =H21+H23 -> 0 | I24: =I21+I23 -> 0 | J24: =J21+J23 -> 0 | ... O24: =O21+O23 -> 0 | S24: =+O24-Q24 -> 0
B25: as % of Revenue | C25: =IFERROR(C24/C8,"na") -> na | D25: =IFERROR(D24/D8,"na") -> na | E25: =IFERROR(E24/E8,"na") -> na | F25: =IFERROR(F24/F8,"na") -> na | G25: =IFERROR(G24/G8,"na") -> na | H25: =IFERROR(H24/H8,"na") -> na | I25: =IFERROR(I24/I8,"na") -> na | J25: =IFERROR(J24/J8,"na") -> na | ... O25: =IFERROR(O24/O8,"na") -> na | Q25: -0.60977489
B26: Restd. Financiero | S26: =+O26-Q26 -> 0
B27: Impuesto sociedades | S27: =+O27-Q27 -> 0
B28: NET INCOME | C28: =C26+C27 -> 0 | D28: =D26+D27 -> 0 | E28: =E26+E27 -> 0 | F28: =F26+F27 -> 0 | G28: =G26+G27 -> 0 | H28: =H26+H27 -> 0 | I28: =I26+I27 -> 0 | J28: =J26+J27 -> 0 | ... O28: =O26+O27 -> 0 | S28: =+O28-Q28 -> 0
C30: =+C4 -> ACTUAL | D30: =+D4 -> ACTUAL | E30: =+E4 -> ACTUAL | F30: =+F4 -> FORECAST | G30: =+G4 -> FORECAST | H30: =+H4 -> FORECAST | I30: =+I4 -> FORECAST | J30: =+J4 -> FORECAST | ... N30: =+N4 -> FORECAST | Q30: BP
B31: Cash Flow | C31: 2026 | D31: 2026 | E31: 2026 | F31: 2026 | G31: 2026 | H31: 2026 | I31: 2026 | J31: 2026 | K31: 2026 | L31: 2026 | M31: 2026 | N31: 2026 | Q31: 2026
C32: Enero | D32: Febrero | E32: Marzo | F32: Abril | G32: Mayo | H32: Junio | I32: Julio | J32: Agosto | K32: Septiembre | L32: Octubre | M32: Noviembre | N32: Diciembre | Q32: Total
B33: CASH-INS | C33: =+SUM(C34:C36) -> 0 | D33: =+SUM(D34:D36) -> 0 | E33: =+SUM(E34:E36) -> 0 | F33: =+F8 -> 0 | G33: =+G8 -> 0 | H33: =+H8 -> 0 | I33: =+I8 -> 0 | J33: =+J8 -> 0 | K33: =+K8 -> 0 | L33: =+L8 -> 0 | M33: =+M8 -> 0 | N33: =+N8 -> 0
B34: Cash position BoP
B35: Revenues
B36: APORTACION K
B37: CASH-OUT | C37: =+SUM(C38:C41) -> 0 | D37: =+SUM(D38:D41) -> 0 | E37: =+SUM(E38:E41) -> 0 | F37: =+SUM(F38:F41) -> 0 | G37: =+SUM(G38:G41) -> 0 | H37: =+SUM(H38:H41) -> 0 | I37: =+SUM(I38:I41) -> 0 | J37: =+SUM(J38:J41) -> 0 | ... N37: =+SUM(N38:N41) -> 0
B38: COGS
B39: Direct Labor
B40: Total OPEX
B41: PROFIT SHARING
B42: CAPEX
B43: TOTAL CASH-OUTS + CAPEX | C43: =+C37+C42 -> 0 | D43: =+D37+D42 -> 0 | E43: =+E37+E42 -> 0 | F43: =+F37+F42 -> 0 | G43: =+G37+G42 -> 0 | H43: =+H37+H42 -> 0 | I43: =+I37+I42 -> 0 | J43: =+J37+J42 -> 0 | ... N43: =+N37+N42 -> 0 | Q43: =+Q37+Q42 -> 0
B44: Costes financieros
...

Sheet Andala
B2: ACTUAL + FORECAST | C2: [Company Name]
C4: ACTUAL | D4: ACTUAL | E4: ACTUAL | F4: ACTUAL | G4: ACTUAL | H4: FORECAST | I4: FORECAST | J4: FORECAST | K4: FORECAST | L4: FORECAST | M4: FORECAST | N4: FORECAST | O4: Actual+Forecast | Q4: BP
B5: Cuenta de Resultados | C5: 2026 | D5: 2026 | E5: 2026 | F5: 2026 | G5: 2026 | H5: 2026 | I5: 2026 | J5: 2026 | K5: 2026 | L5: 2026 | M5: 2026 | N5: 2026 | O5: 2026 | Q5: 2026
C6: Enero | D6: Febrero | E6: Marzo | F6: Abril | G6: Mayo | H6: Junio | I6: Julio | J6: Agosto | K6: Septiembre | L6: Octubre | M6: Noviembre | N6: Diciembre | O6: Total | Q6: Total | S6: Dif | T6: Comentarios
B8: REVENUE | C8: 31835 | D8: 23686 | E8: 26739 | F8: 27986 | G8: 28427.78 | H8: 39214 | I8: 41175 | J8: 43233 | K8: 45395 | L8: 47665 | M8: 50048 | N8: 52550 | O8: =+SUM(C8:N8) -> 457953.78 | Q8: 489055 | S8: =+O8-Q8 -> -31101.22
B9: % Growth | C9: =IFERROR((C8/B8)-1,"na") -> na | D9: =IFERROR((D8/C8)-1,"na") -> -0.25597613 | E9: =IFERROR((E8/D8)-1,"na") -> 0.12889471 | F9: =IFERROR((F8/E8)-1,"na") -> 0.046636 | G9: =IFERROR((G8/F8)-1,"na") -> 0.01578575 | H9: =IFERROR((H8/G8)-1,"na") -> 0.37942534 | I9: =IFERROR((I8/H8)-1,"na") -> 0.05000765 | J9: =IFERROR((J8/I8)-1,"na") -> 0.049981785 | ... N9: =IFERROR((N8/M8)-1,"na") -> 0.049992008
B10: COGS | C10: -17915 | D10: -12828 | E10: -16344 | F10: -16449 | G10: -16019 | H10: -23080 | I10: -24234 | J10: -25445 | K10: -26718 | L10: -28054 | M10: -29456 | N10: -30929 | O10: =+SUM(C10:N10) -> -267471 | Q10: -277206 | S10: =+O10-Q10 -> 9735
B11: GROSS MARGIN | C11: =C8+C10 -> 13920 | D11: =D8+D10 -> 10858 | E11: =E8+E10 -> 10395 | F11: =F8+F10 -> 11537 | G11: =G8+G10 -> 12408.78 | H11: =H8+H10 -> 16134 | I11: =I8+I10 -> 16941 | J11: =J8+J10 -> 17788 | ... O11: =O8+O10 -> 190482.78 | Q11: =Q8+Q10 -> 211849 | S11: =+O11-Q11 -> -21366.22
B12: as % of Revenue | C12: =IFERROR(C11/C8,"na") -> 0.43725459 | D12: =IFERROR(D11/D8,"na") -> 0.45841425 | E12: =IFERROR(E11/E8,"na") -> 0.38875799 | F12: =IFERROR(F11/F8,"na") -> 0.41224184 | G12: =IFERROR(G11/G8,"na") -> 0.4365019 | H12: =IFERROR(H11/H8,"na") -> 0.41143469 | I12: =IFERROR(I11/I8,"na") -> 0.41143898 | J12: =IFERROR(J11/J8,"na") -> 0.41144496 | ... O12: =IFERROR(O11/O8,"na") -> 0.41594324 | Q12: =IFERROR(Q11/Q8,"na") -> 0.43318032
B13: DIRECT LABOR COST | C13: -10451 | D13: -6685 | E13: -13586 | F13: -15528 | G13: -14949 | H13: -15167 | I13: -19833 | J13: -19833 | K13: -19833 | L13: -19833 | M13: -19833 | N13: -19833 | O13: =+SUM(C13:N13) -> -195364 | Q13: -145000 | S13: =+O13-Q13 -> -50364
B14: HEADCOUNT | O14: =+SUM(C14:N14) -> 0
B15: CONTRIBUTION MARGIN | C15: =C8+C10+C13 -> 3469 | D15: =D8+D10+D13 -> 4173 | E15: =E8+E10+E13 -> -3191 | F15: =F8+F10+F13 -> -3991 | G15: =G8+G10+G13 -> -2540.22 | H15: =H8+H10+H13 -> 967 | I15: =I8+I10+I13 -> -2892 | J15: =J8+J10+J13 -> -2045 | ... O15: =O8+O10+O13 -> -4881.22 | Q15: =Q8+Q10+Q13 -> 66849 | S15: =+O15-Q15 -> -71730.22
B16: as % of Revenue | C16: =IFERROR(C15/C8,"na") -> 0.10896812 | D16: =IFERROR(D15/D8,"na") -> 0.17618002 | E16: =IFERROR(E15/E8,"na") -> -0.11933879 | F16: =IFERROR(F15/F8,"na") -> -0.14260702 | G16: =IFERROR(G15/G8,"na") -> -0.08935696 | H16: =IFERROR(H15/H8,"na") -> 0.02465956 | I16: =IFERROR(I15/I8,"na") -> -0.070236794 | J16: =IFERROR(J15/J8,"na") -> -0.04730183 | ... N16: =IFERROR(N15/N8,"na") -> 0.034024738 | O16: =IFERROR(O15/$O$8,"na") -> -0.010658761 | Q16: =IFERROR(Q15/Q8,"na") -> 0.13669015
B17: TOTAL OPERATING EXPENSES (OPEX) | C17: =+C19+C20 -> -29038 | D17: =+D19+D20 -> -23332 | E17: =+E19+E20 -> -24265 | F17: =+F19+F20 -> -22211 | G17: =+G19+G20 -> -21715 | H17: =+H19+H20 -> -32996 | I17: =+I19+I20 -> -32559 | J17: =+J19+J20 -> -33636 | ... O17: =+O19+O20 -> -350929 | Q17: =+Q19+Q20 -> -410619 | S17: =+O17-Q17 -> 59690
B18: as % of Revenue | C18: =IFERROR(C17/C8,"na") -> -0.91214073 | D18: =IFERROR(D17/D8,"na") -> -0.98505446 | E18: =IFERROR(E17/E8,"na") -> -0.90747597 | F18: =IFERROR(F17/F8,"na") -> -0.79364682 | G18: =IFERROR(G17/G8,"na") -> -0.76386549 | H18: =IFERROR(H17/H8,"na") -> -0.84143418 | I18: =IFERROR(I17/I8,"na") -> -0.79074681 | J18: =IFERROR(J17/J8,"na") -> -0.77801679 | ... N18: =IFERROR(N17/N8,"na") -> -0.62616556 | O18: =IFERROR(O17/$O$8,"na") -> -0.76629786 | Q18: =IFERROR(Q17/$O$8,"na") -> -0.89663852
B19: MKT (agencias, paid, fees amazon,etc) | C19: -12995 | D19: -10699 | E19: -8156 | F19: -6268 | G19: -5780 | H19: -14050 | I19: -14050 | J19: -14050 | K19: -14050 | L19: -14050 | M19: -14050 | N19: -14050 | O19: =+SUM(C19:N19) -> -142248 | Q19: -289850 | S19: =+O19-Q19 -> 147602
B20: Other OPEX | C20: -16043 | D20: -12633 | E20: -16109 | F20: -15943 | G20: -15935 | H20: -18946 | I20: -18509 | J20: -19586 | K20: -18637 | L20: -18706 | M20: -18779 | N20: -18855 | O20: =+SUM(C20:N20) -> -208681 | Q20: -120769 | S20: =+O20-Q20 -> -87912
B21: EBITDA | C21: =C15+C17 -> -25569 | D21: =D15+D17 -> -19159 | E21: =E15+E17 -> -27456 | F21: =F15+F17 -> -26202 | G21: =G15+G17 -> -24255.22 | H21: =H15+H17 -> -32029 | I21: =I15+I17 -> -35451 | J21: =J15+J17 -> -35681 | ... O21: =O15+O17 -> -355810.22 | Q21: =Q15+Q17 -> -343770 | S21: =+O21-Q21 -> -12040.22
B22: as % of Revenue | C22: =IFERROR(C21/C8,"na") -> -0.80317261 | D22: =IFERROR(D21/D8,"na") -> -0.80887444 | E22: =IFERROR(E21/E8,"na") -> -1.0268148 | F22: =IFERROR(F21/F8,"na") -> -0.93625384 | G22: =IFERROR(G21/G8,"na") -> -0.85322245 | H22: =IFERROR(H21/H8,"na") -> -0.81677462 | I22: =IFERROR(I21/I8,"na") -> -0.86098361 | J22: =IFERROR(J21/J8,"na") -> -0.82531862 | ... O22: =IFERROR(O21/O8,"na") -> -0.77695662 | Q22: =IFERROR(Q21/Q8,"na") -> -0.70292707
B23: Amortizaciones | G23: -3880 | H23: -3880 | I23: -3880 | S23: =+O23-Q23 -> 0
B24: EBIT | C24: =C21+C23 -> -25569 | D24: =D21+D23 -> -19159 | E24: =E21+E23 -> -27456 | F24: =F21+F23 -> -26202 | G24: =G21+G23 -> -28135.22 | H24: =H21+H23 -> -35909 | I24: =I21+I23 -> -39331 | J24: =J21+J23 -> -35681 | ... O24: =O21+O23 -> -355810.22 | Q24: =Q21+Q23 -> -343770 | S24: =+O24-Q24 -> -12040.22
B25: as % of Revenue | C25: =IFERROR(C24/C8,"na") -> -0.80317261 | D25: =IFERROR(D24/D8,"na") -> -0.80887444 | E25: =IFERROR(E24/E8,"na") -> -1.0268148 | F25: =IFERROR(F24/F8,"na") -> -0.93625384 | G25: =IFERROR(G24/G8,"na") -> -0.98970866 | H25: =IFERROR(H24/H8,"na") -> -0.91571888 | I25: =IFERROR(I24/I8,"na") -> -0.95521554 | J25: =IFERROR(J24/J8,"na") -> -0.82531862 | ... O25: =IFERROR(O24/O8,"na") -> -0.77695662 | Q25: -0.60977489
B26: Restd. Financiero | S26: =+O26-Q26 -> 0
B27: Impuesto sociedades | S27: =+O27-Q27 -> 0
B28: NET INCOME | C28: =C26+C27 -> 0 | D28: =D26+D27 -> 0 | E28: =E26+E27 -> 0 | F28: =F26+F27 -> 0 | G28: =G26+G27 -> 0 | H28: =H26+H27 -> 0 | I28: =I26+I27 -> 0 | J28: =J26+J27 -> 0 | ... O28: =O26+O27 -> 0 | S28: =+O28-Q28 -> 0
C30: =+C4 -> ACTUAL | D30: =+D4 -> ACTUAL | E30: =+E4 -> ACTUAL | F30: =+F4 -> ACTUAL | G30: =+G4 -> ACTUAL | H30: =+H4 -> FORECAST | I30: =+I4 -> FORECAST | J30: =+J4 -> FORECAST | ... N30: =+N4 -> FORECAST | Q30: BP
B31: Cash Flow | C31: 2026 | D31: 2026 | E31: 2026 | F31: 2026 | G31: 2026 | H31: 2026 | I31: 2026 | J31: 2026 | K31: 2026 | L31: 2026 | M31: 2026 | N31: 2026 | Q31: 2026
C32: Enero | D32: Febrero | E32: Marzo | F32: Abril | G32: Mayo | H32: Junio | I32: Julio | J32: Agosto | K32: Septiembre | L32: Octubre | M32: Noviembre | N32: Diciembre | Q32: Total
B33: CASH-INS | C33: =+SUM(C34:C36) -> 0 | D33: =+SUM(D34:D36) -> 0 | E33: =+SUM(E34:E36) -> 0 | F33: =+F8 -> 27986 | G33: =+G8 -> 28427.78 | H33: =+H8 -> 39214 | I33: =+I8 -> 41175 | J33: =+J8 -> 43233 | K33: =+K8 -> 45395 | L33: =+L8 -> 47665 | M33: =+M8 -> 50048 | N33: =+N8 -> 52550
B34: Cash position BoP
B35: Revenues
B36: APORTACION K
B37: CASH-OUT | C37: =+SUM(C38:C41) -> 0 | D37: =+SUM(D38:D41) -> 0 | E37: =+SUM(E38:E41) -> 0 | F37: =+SUM(F38:F41) -> 0 | G37: =+SUM(G38:G41) -> 0 | H37: =+SUM(H38:H41) -> 0 | I37: =+SUM(I38:I41) -> 0 | J37: =+SUM(J38:J41) -> 0 | ... N37: =+SUM(N38:N41) -> 0
B38: COGS
B39: Direct Labor
B40: Total OPEX
B41: PROFIT SHARING
B42: CAPEX
B43: TOTAL CASH-OUTS + CAPEX | C43: =+C37+C42 -> 0 | D43: =+D37+D42 -> 0 | E43: =+E37+E42 -> 0 | F43: =+F37+F42 -> 0 | G43: =+G37+G42 -> 0 | H43: =+H37+H42 -> 0 | I43: =+I37+I42 -> 0 | J43: =+J37+J42 -> 0 | ... N43: =+N37+N42 -> 0 | Q43: =+Q37+Q42 -> 0
B44: Costes financieros
...

Sheet Arandovo
B2: ACTUALS + FORECAST | C2: Arandovo
C4: ACTUAL | D4: ACTUAL | E4: ACTUAL | F4: ACTUAL | G4: ACTUAL | H4: FORECAST | I4: FORECAST | J4: FORECAST | K4: FORECAST | L4: FORECAST | M4: FORECAST | N4: FORECAST | O4: Actuals + Forecast | Q4: BP
B5: Cuenta de Resultados | C5: 2026 | D5: 2026 | E5: 2026 | F5: 2026 | G5: 2026 | H5: 2026 | I5: 2026 | J5: 2026 | K5: 2026 | L5: 2026 | M5: 2026 | N5: 2026 | O5: 2026 | Q5: 2026
C6: Enero | D6: Febrero | E6: Marzo | F6: Abril | G6: Mayo | H6: Junio | I6: Julio | J6: Agosto | K6: Septiembre | L6: Octubre | M6: Noviembre | N6: Diciembre | O6: Total | Q6: Total | S6: Dif | T6: Comentarios
B8: REVENUE | C8: 34152.61 | D8: 13536.28 | E8: 99915.24 | F8: 106600.47 | G8: 46742.21 | H8: 5900 | I8: 35900 | J8: 31900 | K8: 136690 | L8: 115298 | M8: 120650 | N8: 156012 | O8: =+SUM(C8:N8) -> 903296.81 | Q8: 935284 | S8: =+O8-Q8 -> -31987.19
B9: % Growth | C9: =IFERROR((C8/B8)-1,"na") -> na | D9: =IFERROR((D8/C8)-1,"na") -> -0.60365313 | E9: =IFERROR((E8/D8)-1,"na") -> 6.3812923 | F9: =IFERROR((F8/E8)-1,"na") -> 0.066909012 | G9: =IFERROR((G8/F8)-1,"na") -> -0.56151966 | H9: =IFERROR((H8/G8)-1,"na") -> -0.87377576 | I9: =IFERROR((I8/H8)-1,"na") -> 5.0847458 | J9: =IFERROR((J8/I8)-1,"na") -> -0.11142061 | ... N9: =IFERROR((N8/M8)-1,"na") -> 0.29309573
B10: COGS | C10: -14447.03 | D10: -25353.6 | E10: -22309.48 | F10: -29285.4 | G10: -28174.81 | H10: -22165.27 | I10: -22165.27 | J10: -22165.27 | K10: -22190.27 | L10: -22190.27 | M10: -22190.27 | N10: -22484.27 | O10: =+SUM(C10:N10) -> -275121.21 | Q10: -294278.2 | S10: =+O10-Q10 -> 19156.99
B11: GROSS MARGIN | C11: =+C8+C10 -> 19705.58 | D11: =+D8+D10 -> -11817.32 | E11: =+E8+E10 -> 77605.76 | F11: =+F8+F10 -> 77315.07 | G11: =+G8+G10 -> 18567.4 | H11: =+H8+H10 -> -16265.27 | I11: =+I8+I10 -> 13734.73 | J11: =+J8+J10 -> 9734.73 | ... O11: =+O8+O10 -> 628175.6 | Q11: 641005.8 | S11: =+O11-Q11 -> -12830.2
B12: as % of Revenue | C12: =IFERROR(C11/C8,"na") -> 0.57698606 | D12: =IFERROR(D11/D8,"na") -> -0.8730109 | E12: =IFERROR(E11/E8,"na") -> 0.77671594 | F12: =IFERROR(F11/F8,"na") -> 0.72527888 | G12: =IFERROR(G11/G8,"na") -> 0.39722983 | H12: =IFERROR(H11/H8,"na") -> -2.7568254 | I12: =IFERROR(I11/I8,"na") -> 0.38258301 | J12: =IFERROR(J11/J8,"na") -> 0.30516395 | ... O12: =IFERROR(O11/O8,"na") -> 0.69542546 | Q12: na
B13: DIRECT LABOR COST | C13: -32274.64 | D13: -46691.91 | E13: -54357.4 | F13: -73923.08 | G13: -64206.21 | H13: -59533.828 | I13: -59523.828 | J13: -59593.737 | K13: -59503.737 | L13: -59503.737 | M13: -59503.737 | N13: -59503.737 | O13: =+SUM(C13:N13) -> -688119.58 | Q13: -682704 | S13: =+O13-Q13 -> -5415.583
B14: HEADCOUNT | O14: 0
B15: CONTRIBUTION MARGIN | C15: =+C11+C13 -> -12569.06 | D15: =+D11+D13 -> -58509.23 | E15: =+E11+E13 -> 23248.36 | F15: =+F11+F13 -> 3391.99 | G15: =+G11+G13 -> -45638.81 | H15: =+H11+H13 -> -75799.098 | I15: =+I11+I13 -> -45789.098 | J15: =+J11+J13 -> -49859.007 | ... O15: =+O11+O13 -> -59943.982 | Q15: -41698.199 | S15: =+O15-Q15 -> -18245.783
B16: as % of Revenue | C16: =IFERROR(C15/C8,"na") -> -0.36802634 | D16: =IFERROR(D15/D8,"na") -> -4.322401 | E16: =IFERROR(E15/E8,"na") -> 0.23268082 | F16: =IFERROR(F15/F8,"na") -> 0.031819653 | G16: =IFERROR(G15/G8,"na") -> -0.97639393 | H16: =IFERROR(H15/H8,"na") -> -12.847305 | I16: =IFERROR(I15/I8,"na") -> -1.2754623 | J16: =IFERROR(J15/J8,"na") -> -1.5629783 | ... O16: =IFERROR(O15/O8,"na") -> -0.066361335 | Q16: na
B17: TOTAL OPERATING EXPENSES (OPEX) | C17: =+C19+C20 -> -9873.92 | D17: =+D19+D20 -> -25833.75 | E17: =+E19+E20 -> -8173.24 | F17: =+F19+F20 -> -7308.4 | G17: =+G19+G20 -> -19884.62 | H17: =+H19+H20 -> -35435.897 | I17: =+I19+I20 -> -27082.897 | J17: =+J19+J20 -> -27082.897 | ... O17: =+O19+O20 -> -270160.21 | Q17: -325025.76 | S17: =+O17-Q17 -> 54865.553
B18: as % of Revenue | C18: =+IFERROR(C17/C8,"na") -> -0.28911173 | D18: =+IFERROR(D17/D8,"na") -> -1.9084822 | E18: =+IFERROR(E17/E8,"na") -> -0.081801735 | F18: =+IFERROR(F17/F8,"na") -> -0.068558797 | G18: =+IFERROR(G17/G8,"na") -> -0.42541035 | H18: =+IFERROR(H17/H8,"na") -> -6.0060842 | I18: =+IFERROR(I17/I8,"na") -> -0.75439824 | J18: =+IFERROR(J17/J8,"na") -> -0.84899363 | ... O18: =+IFERROR(O17/O8,"na") -> -0.29908243 | Q18: 0
B19: MKT (agencias, paid, fees amazon,etc) | C19: 0 | D19: -9929 | E19: -815 | F19: -2170.2 | G19: -2259.6 | H19: -18237.05 | I19: -9884.05 | J19: -9884.05 | K19: -9884.05 | L19: -9884.05 | M19: -9884.05 | N19: -9884.05 | O19: =+SUM(C19:N19) -> -92715.15 | Q19: -118608.6 | S19: =+O19-Q19 -> 25893.45
B20: Other OPEX | C20: -9873.92 | D20: -15904.75 | E20: -7358.24 | F20: -5138.2 | G20: -17625.02 | H20: -17198.847 | I20: -17198.847 | J20: -17198.847 | K20: -17198.847 | L20: -17198.847 | M20: -17198.847 | N20: -18351.847 | O20: =+SUM(C20:N20) -> -177445.06 | Q20: -206417.16 | S20: =+O20-Q20 -> 28972.103
B21: EBITDA | C21: =+C15+C17 -> -22442.98 | D21: =+D15+D17 -> -84342.98 | E21: =+E15+E17 -> 15075.12 | F21: =+F15+F17 -> -3916.41 | G21: =+G15+G17 -> -65523.43 | H21: =+H15+H17 -> -111234.99 | I21: =+I15+I17 -> -72871.995 | J21: =+J15+J17 -> -76941.904 | ... O21: =+O15+O17 -> -330104.19 | Q21: -366723.96 | S21: =+O21-Q21 -> 36619.77
B22: as % of Revenue | C22: =+IFERROR(C21/C8,"na") -> -0.65713806 | D22: =+IFERROR(D21/D8,"na") -> -6.2308832 | E22: =+IFERROR(E21/E8,"na") -> 0.15087909 | F22: =+IFERROR(F21/F8,"na") -> -0.036739144 | G22: =+IFERROR(G21/G8,"na") -> -1.4018043 | H22: =+IFERROR(H21/H8,"na") -> -18.853389 | I22: =+IFERROR(I21/I8,"na") -> -2.0298606 | J22: =+IFERROR(J21/J8,"na") -> -2.4119719 | ... O22: =+IFERROR(O21/O8,"na") -> -0.36544377 | Q22: na
B23: Amortizaciones | C23: -4350.75 | D23: -4350.76 | E23: -4350.73 | F23: -4416.09 | G23: -4416.14 | H23: -4433.39 | I23: -4433.39 | J23: -4433.39 | K23: -4433.39 | L23: -4433.39 | M23: -4433.39 | N23: -4502.39 | O23: =+SUM(C23:N23) -> -52987.2 | Q23: -48954.6 | S23: =+O23-Q23 -> -4032.6
B24: EBIT | C24: =+C21+C23 -> -26793.73 | D24: =+D21+D23 -> -88693.74 | E24: =+E21+E23 -> 10724.39 | F24: =+F21+F23 -> -8332.5 | G24: =+G21+G23 -> -69939.57 | H24: =+H21+H23 -> -115668.38 | I24: =+I21+I23 -> -77305.385 | J24: =+J21+J23 -> -81375.294 | ... O24: =+O21+O23 -> -383091.39 | Q24: -415678.56 | S24: =+O24-Q24 -> 32587.17
B25: as % of Revenue | C25: =+IFERROR(C24/C8,"na") -> -0.7845295 | D25: =+IFERROR(D24/D8,"na") -> -6.552298 | E25: =+IFERROR(E24/E8,"na") -> 0.10733488 | F25: =+IFERROR(F24/F8,"na") -> -0.078165697 | G25: =+IFERROR(G24/G8,"na") -> -1.4962829 | H25: =+IFERROR(H24/H8,"na") -> -19.604811 | I25: =+IFERROR(I24/I8,"na") -> -2.1533533 | J25: =+IFERROR(J24/J8,"na") -> -2.5509497 | ... O25: =+IFERROR(O24/O8,"na") -> -0.42410356 | Q25: -0.61
B26: Restd. Financiero | C26: -158.06 | D26: -140.57 | E26: -293.1 | F26: -405.05 | G26: -560.1 | H26: -298.93333 | I26: -298.93333 | J26: -298.93333 | K26: -298.93333 | L26: -298.93333 | M26: -298.93333 | N26: -321.93333 | O26: =+SUM(C26:N26) -> -3672.4133 | Q26: -870 | S26: =+O26-Q26 -> -2802.4133
B27: Impuesto sociedades | C27: -45.34 | D27: -45.34 | E27: -45.34 | F27: -45.34 | G27: -45.34 | H27: -45 | I27: -45 | J27: -45 | K27: -45 | L27: -45 | M27: -45 | N27: -45 | O27: =+SUM(C27:N27) -> -541.7 | Q27: -540 | S27: =+O27-Q27 -> -1.7
B28: NET INCOME | C28: =+C24+C26+C27 -> -26997.13 | D28: =+D24+D26+D27 -> -88879.65 | E28: =+E24+E26+E27 -> 10385.95 | F28: =+F24+F26+F27 -> -8782.89 | G28: =+G24+G26+G27 -> -70545.01 | H28: =+H24+H26+H27 -> -116012.32 | I28: =+I24+I26+I27 -> -77649.318 | J28: =+J24+J26+J27 -> -81719.227 | ... O28: =+O24+O26+O27 -> -387305.5 | Q28: -417088.56 | S28: =+O28-Q28 -> 29783.057
C30: ACTUAL | D30: ACTUAL | E30: ACTUAL | F30: FORECAST | G30: FORECAST | H30: FORECAST | I30: FORECAST | J30: FORECAST | K30: FORECAST | L30: FORECAST | M30: FORECAST | N30: FORECAST | Q30: BP
B31: Cash Flow | C31: 2026 | D31: 2026 | E31: 2026 | F31: 2026 | G31: 2026 | H31: 2026 | I31: 2026 | J31: 2026 | K31: 2026 | L31: 2026 | M31: 2026 | N31: 2026 | Q31: 2026
C32: Enero | D32: Febrero | E32: Marzo | F32: Abril | G32: Mayo | H32: Junio | I32: Julio | J32: Agosto | K32: Septiembre | L32: Octubre | M32: Noviembre | N32: Diciembre | Q32: Total
B33: CASH-INS | C33: 0 | D33: 0 | E33: 0 | F33: 0 | G33: 0 | H33: 0 | I33: 0 | J33: 0 | K33: 0 | L33: 0 | M33: 0 | N33: 0
B34: Cash position BoP
B35: Revenues
B36: APORTACION K
B37: CASH-OUT | C37: 0 | D37: 0 | E37: 0 | F37: 0 | G37: 0 | H37: 0 | I37: 0 | J37: 0 | K37: 0 | L37: 0 | M37: 0 | N37: 0
B38: COGS
B39: Direct Labor
B40: Total OPEX
B41: PROFIT SHARING
B42: CAPEX
B43: TOTAL CASH-OUTS + CAPEX | C43: 0 | D43: 0 | E43: 0 | F43: 0 | G43: 0 | H43: 0 | I43: 0 | J43: 0 | K43: 0 | L43: 0 | M43: 0 | N43: 0 | Q43: 0
B44: Costes financieros
...

Sheet Mendrugo
B2: ACTUALS + FORECAST | C2: MENDRUGO
C4: ACTUAL | D4: ACTUAL | E4: ACTUAL | F4: ACTUAL | G4: ACTUAL | H4: FORECAST | I4: FORECAST | J4: FORECAST | K4: FORECAST | L4: FORECAST | M4: FORECAST | N4: FORECAST | O4: Actuals + Forecast | Q4: BP
B5: Cuenta de Resultados | C5: 2026 | D5: 2026 | E5: 2026 | F5: 2026 | G5: 2026 | H5: 2026 | I5: 2026 | J5: 2026 | K5: 2026 | L5: 2026 | M5: 2026 | N5: 2026 | O5: 2026 | Q5: 2026
C6: Enero | D6: Febrero | E6: Marzo | F6: Abril | G6: Mayo | H6: Junio | I6: Julio | J6: Agosto | K6: Septiembre | L6: Octubre | M6: Noviembre | N6: Diciembre | O6: Total | Q6: Total | S6: Dif | T6: Comentarios
B8: REVENUE | C8: 23781 | D8: 22166 | E8: 25375 | F8: 26753 | G8: 20641 | O8: =+SUM(C8:N8) -> 118716 | S8: =+O8-Q8 -> 118716
B9: % Growth | C9: =IFERROR((C8/B8)-1,"na") -> na | D9: =IFERROR((D8/C8)-1,"na") -> -0.067911358 | E9: =IFERROR((E8/D8)-1,"na") -> 0.14477127 | F9: =IFERROR((F8/E8)-1,"na") -> 0.054305419 | G9: =IFERROR((G8/F8)-1,"na") -> -0.22846036 | H9: =IFERROR((H8/G8)-1,"na") -> -1 | I9: =IFERROR((I8/H8)-1,"na") -> na | J9: =IFERROR((J8/I8)-1,"na") -> na | ... N9: =IFERROR((N8/M8)-1,"na") -> na
B10: COGS | C10: -7711 | D10: -8692 | E10: -8944 | F10: -10096 | G10: -8119 | O10: =+SUM(C10:N10) -> -43562 | S10: =+O10-Q10 -> -43562
B11: GROSS MARGIN | C11: =C8+C10 -> 16070 | D11: =D8+D10 -> 13474 | E11: =E8+E10 -> 16431 | F11: =F8+F10 -> 16657 | G11: =G8+G10 -> 12522 | H11: =H8+H10 -> 0 | I11: =I8+I10 -> 0 | J11: =J8+J10 -> 0 | ... O11: =O8+O10 -> 75154 | Q11: =Q8+Q10 -> 0 | S11: =+O11-Q11 -> 75154
B12: as % of Revenue | C12: =IFERROR(C11/C8,"na") -> 0.67574955 | D12: =IFERROR(D11/D8,"na") -> 0.60786791 | E12: =IFERROR(E11/E8,"na") -> 0.64752709 | F12: =IFERROR(F11/F8,"na") -> 0.62262176 | G12: =IFERROR(G11/G8,"na") -> 0.60665665 | H12: =IFERROR(H11/H8,"na") -> na | I12: =IFERROR(I11/I8,"na") -> na | J12: =IFERROR(J11/J8,"na") -> na | ... O12: =IFERROR(O11/O8,"na") -> 0.63305704 | Q12: =IFERROR(Q11/Q8,"na") -> na
B13: DIRECT LABOR COST | C13: -20717.42 | D13: -22253.88 | E13: -21680.51 | F13: -21897.05 | G13: -22192.99 | O13: =+SUM(C13:N13) -> -108741.85 | S13: =+O13-Q13 -> -108741.85
B14: HEADCOUNT | C14: 7 | D14: 8 | E14: 8 | F14: 8 | G14: 8 | O14: =+SUM(C14:N14) -> 39
B15: CONTRIBUTION MARGIN | C15: =C8+C10+C13 -> -4647.42 | D15: =D8+D10+D13 -> -8779.88 | E15: =E8+E10+E13 -> -5249.51 | F15: =F8+F10+F13 -> -5240.05 | G15: =G8+G10+G13 -> -9670.99 | H15: =H8+H10+H13 -> 0 | I15: =I8+I10+I13 -> 0 | J15: =J8+J10+J13 -> 0 | ... O15: =O8+O10+O13 -> -33587.85 | Q15: =Q8+Q10+Q13 -> 0 | S15: =+O15-Q15 -> -33587.85
B16: as % of Revenue | C16: =IFERROR(C15/C8,"na") -> -0.19542576 | D16: =IFERROR(D15/D8,"na") -> -0.39609672 | E16: =IFERROR(E15/E8,"na") -> -0.20687724 | F16: =IFERROR(F15/F8,"na") -> -0.19586775 | G16: =IFERROR(G15/G8,"na") -> -0.46853302 | H16: =IFERROR(H15/H8,"na") -> na | I16: =IFERROR(I15/I8,"na") -> na | J16: =IFERROR(J15/J8,"na") -> na | ... N16: =IFERROR(N15/N8,"na") -> na | O16: =IFERROR(O15/$O$8,"na") -> -0.28292606 | Q16: =IFERROR(Q15/Q8,"na") -> na
B17: TOTAL OPERATING EXPENSES (OPEX) | C17: -16371 | D17: -18996 | E17: -16044 | F17: -19524 | G17: -17226 | H17: =+H19+H20 -> 0 | I17: =+I19+I20 -> 0 | J17: =+J19+J20 -> 0 | K17: =+K19+K20 -> 0 | L17: =+L19+L20 -> 0 | M17: =+M19+M20 -> 0 | N17: =+N19+N20 -> 0 | O17: =+O19+O20 -> -88161 | Q17: =+Q19+Q20 -> 0 | S17: =+O17-Q17 -> -88161
B18: as % of Revenue | C18: =IFERROR(C17/C8,"na") -> -0.68840671 | D18: =IFERROR(D17/D8,"na") -> -0.85698818 | E18: =IFERROR(E17/E8,"na") -> -0.63227586 | F18: =IFERROR(F17/F8,"na") -> -0.72978731 | G18: =IFERROR(G17/G8,"na") -> -0.83455259 | H18: =IFERROR(H17/H8,"na") -> na | I18: =IFERROR(I17/I8,"na") -> na | J18: =IFERROR(J17/J8,"na") -> na | ... N18: =IFERROR(N17/N8,"na") -> na | O18: =IFERROR(O17/$O$8,"na") -> -0.74262105 | Q18: =IFERROR(Q17/$O$8,"na") -> 0
B19: MKT (agencias, paid, fees amazon,etc) | C19: -7265 | D19: -8208 | E19: -6081 | F19: -8525 | G19: -8171 | O19: =+SUM(C19:N19) -> -38250 | S19: =+O19-Q19 -> -38250
B20: Other OPEX | C20: =+C17-C19 -> -9106 | D20: =+D17-D19 -> -10788 | E20: =+E17-E19 -> -9963 | F20: =+F17-F19 -> -10999 | G20: =+G17-G19 -> -9055 | O20: =+SUM(C20:N20) -> -49911 | S20: =+O20-Q20 -> -49911
B21: EBITDA | C21: =C15+C17 -> -21018.42 | D21: =D15+D17 -> -27775.88 | E21: =E15+E17 -> -21293.51 | F21: =F15+F17 -> -24764.05 | G21: =G15+G17 -> -26896.99 | H21: =H15+H17 -> 0 | I21: =I15+I17 -> 0 | J21: =J15+J17 -> 0 | ... O21: =O15+O17 -> -121748.85 | Q21: =Q15+Q17 -> 0 | S21: =+O21-Q21 -> -121748.85
B22: as % of Revenue | C22: =IFERROR(C21/C8,"na") -> -0.88383247 | D22: =IFERROR(D21/D8,"na") -> -1.2530849 | E22: =IFERROR(E21/E8,"na") -> -0.8391531 | F22: =IFERROR(F21/F8,"na") -> -0.92565507 | G22: =IFERROR(G21/G8,"na") -> -1.3030856 | H22: =IFERROR(H21/H8,"na") -> na | I22: =IFERROR(I21/I8,"na") -> na | J22: =IFERROR(J21/J8,"na") -> na | ... O22: =IFERROR(O21/O8,"na") -> -1.0255471 | Q22: =IFERROR(Q21/Q8,"na") -> na
B23: Amortizaciones | S23: =+O23-Q23 -> 0
B24: EBIT | C24: =C21+C23 -> -21018.42 | D24: =D21+D23 -> -27775.88 | E24: =E21+E23 -> -21293.51 | F24: =F21+F23 -> -24764.05 | G24: =G21+G23 -> -26896.99 | H24: =H21+H23 -> 0 | I24: =I21+I23 -> 0 | J24: =J21+J23 -> 0 | ... O24: =O21+O23 -> -121748.85 | Q24: =Q21+Q23 -> 0 | S24: =+O24-Q24 -> -121748.85
B25: as % of Revenue | C25: =IFERROR(C24/C8,"na") -> -0.88383247 | D25: =IFERROR(D24/D8,"na") -> -1.2530849 | E25: =IFERROR(E24/E8,"na") -> -0.8391531 | F25: =IFERROR(F24/F8,"na") -> -0.92565507 | G25: =IFERROR(G24/G8,"na") -> -1.3030856 | H25: =IFERROR(H24/H8,"na") -> na | I25: =IFERROR(I24/I8,"na") -> na | J25: =IFERROR(J24/J8,"na") -> na | ... O25: =IFERROR(O24/O8,"na") -> -1.0255471 | Q25: -0.60977489
B26: Restd. Financiero | S26: =+O26-Q26 -> 0
B27: Impuesto sociedades | Q27: 0 | S27: =+O27-Q27 -> 0
B28: NET INCOME | C28: =+C24+C26+C27 -> -21018.42 | D28: =+D24+D26+D27 -> -27775.88 | E28: =+E24+E26+E27 -> -21293.51 | F28: =+F24+F26+F27 -> -24764.05 | G28: =+G24+G26+G27 -> -26896.99 | H28: =+H24+H26+H27 -> 0 | I28: =+I24+I26+I27 -> 0 | J28: =+J24+J26+J27 -> 0 | ... O28: =+O24+O26+O27 -> -121748.85 | Q28: =+Q24+Q26+Q27 -> 0 | S28: =+O28-Q28 -> -121748.85
C30: =+C4 -> ACTUAL | D30: =+D4 -> ACTUAL | E30: =+E4 -> ACTUAL | F30: =+F4 -> ACTUAL | G30: =+G4 -> ACTUAL | H30: =+H4 -> FORECAST | I30: =+I4 -> FORECAST | J30: =+J4 -> FORECAST | ... N30: =+N4 -> FORECAST | Q30: BP
B31: Cash Flow | C31: 2026 | D31: 2026 | E31: 2026 | F31: 2026 | G31: 2026 | H31: 2026 | I31: 2026 | J31: 2026 | K31: 2026 | L31: 2026 | M31: 2026 | N31: 2026 | Q31: 2026
C32: Enero | D32: Febrero | E32: Marzo | F32: Abril | G32: Mayo | H32: Junio | I32: Julio | J32: Agosto | K32: Septiembre | L32: Octubre | M32: Noviembre | N32: Diciembre | Q32: Total
B33: CASH-INS | C33: =+SUM(C34:C36) -> 0 | D33: =+SUM(D34:D36) -> #REF! | E33: =+SUM(E34:E36) -> 100000 | F33: =+F8 -> 26753 | G33: =+G8 -> 20641 | H33: =+H8 -> 0 | I33: =+I8 -> 0 | J33: =+J8 -> 0 | K33: =+K8 -> 0 | L33: =+L8 -> 0 | M33: =+M8 -> 0 | N33: =+N8 -> 0
B34: Cash position BoP
B35: Revenues
B36: APORTACION K | D36: =+#REF! -> #REF! | E36: 100000
B37: CASH-OUT | C37: =+SUM(C38:C41) -> 0 | D37: =+SUM(D38:D41) -> 0 | E37: =+SUM(E38:E41) -> 0 | F37: =+SUM(F38:F41) -> 0 | G37: =+SUM(G38:G41) -> 0 | H37: =+SUM(H38:H41) -> 0 | I37: =+SUM(I38:I41) -> 0 | J37: =+SUM(J38:J41) -> 0 | ... N37: =+SUM(N38:N41) -> 0
B38: COGS
B39: Direct Labor
B40: Total OPEX
B41: PROFIT SHARING
B42: CAPEX
B43: TOTAL CASH-OUTS + CAPEX | C43: =+C37+C42 -> 0 | D43: =+D37+D42 -> 0 | E43: =+E37+E42 -> 0 | F43: =+F37+F42 -> 0 | G43: =+G37+G42 -> 0 | H43: =+H37+H42 -> 0 | I43: =+I37+I42 -> 0 | J43: =+J37+J42 -> 0 | ... N43: =+N37+N42 -> 0 | Q43: =+Q37+Q42 -> 0
B44: Costes financieros | D44: =+#REF! -> #REF! | E44: =+#REF! -> #REF! | F44: =+#REF! -> #REF! | G44: =+#REF! -> #REF! | H44: =+#REF! -> #REF! | I44: =+#REF! -> #REF! | J44: =+#REF! -> #REF! | K44: =+#REF! -> #REF! | ... N44: =+#REF! -> #REF!
...

Sheet Mica
B2: ACTUALS + FORECAST | C2: Mica
C4: ACTUAL | D4: ACTUAL | E4: ACTUAL | F4: ACTUAL | G4: FORECAST | H4: FORECAST | I4: FORECAST | J4: FORECAST | K4: FORECAST | L4: FORECAST | M4: FORECAST | N4: FORECAST | O4: Actuals + Forecast | Q4: BP
B5: Cuenta de Resultados | C5: 2026 | D5: 2026 | E5: 2026 | F5: 2026 | G5: 2026 | H5: 2026 | I5: 2026 | J5: 2026 | K5: 2026 | L5: 2026 | M5: 2026 | N5: 2026 | O5: 2026 | Q5: 2026
C6: Enero | D6: Febrero | E6: Marzo | F6: Abril | G6: Mayo | H6: Junio | I6: Julio | J6: Agosto | K6: Septiembre | L6: Octubre | M6: Noviembre | N6: Diciembre | O6: Total | Q6: Total | S6: Dif | T6: Comentarios
B8: REVENUE | C8: 40598 | D8: 46039 | E8: 42218 | F8: 26686 | G8: 140596 | H8: 153230 | I8: 164773 | J8: 190082 | K8: 156685 | L8: 165023 | M8: 154639 | N8: 131178 | O8: =+SUM(C8:N8) -> 1411747 | Q8: 1535250 | S8: =+O8-Q8 -> -123503
B9: % Growth | C9: =IFERROR((C8/B8)-1,"na") -> na | D9: =IFERROR((D8/C8)-1,"na") -> 0.13402138 | E9: =IFERROR((E8/D8)-1,"na") -> -0.082994852 | F9: =IFERROR((F8/E8)-1,"na") -> -0.36789995 | G9: =IFERROR((G8/F8)-1,"na") -> 4.2685303 | H9: =IFERROR((H8/G8)-1,"na") -> 0.089860309 | I9: =IFERROR((I8/H8)-1,"na") -> 0.075331201 | J9: =IFERROR((J8/I8)-1,"na") -> 0.15359919 | ... N9: =IFERROR((N8/M8)-1,"na") -> -0.15171464
B10: COGS | C10: -16089 | D10: -46105 | E10: -15501 | F10: -16240 | G10: -34867 | H10: -34867 | I10: -34867 | J10: -34867 | K10: -34867 | L10: -34867 | M10: -34867 | N10: -35067 | O10: =+SUM(C10:N10) -> -373071 | Q10: -418600 | S10: =+O10-Q10 -> 45529
B11: GROSS MARGIN | C11: =C8+C10 -> 24509 | D11: =D8+D10 -> -66 | E11: =E8+E10 -> 26717 | F11: =F8+F10 -> 10446 | G11: =G8+G10 -> 105729 | H11: =H8+H10 -> 118363 | I11: =I8+I10 -> 129906 | J11: =J8+J10 -> 155215 | ... O11: =O8+O10 -> 1038676 | Q11: =Q8+Q10 -> 1116650 | S11: =+O11-Q11 -> -77974
B12: as % of Revenue | C12: =IFERROR(C11/C8,"na") -> 0.60369969 | D12: =IFERROR(D11/D8,"na") -> -0.0014335672 | E12: =IFERROR(E11/E8,"na") -> 0.63283434 | F12: =IFERROR(F11/F8,"na") -> 0.39144121 | G12: =IFERROR(G11/G8,"na") -> 0.75200575 | H12: =IFERROR(H11/H8,"na") -> 0.77245317 | I12: =IFERROR(I11/I8,"na") -> 0.78839373 | J12: =IFERROR(J11/J8,"na") -> 0.81656864 | ... O12: =IFERROR(O11/O8,"na") -> 0.73573806 | Q12: =IFERROR(Q11/Q8,"na") -> 0.72734082
B13: DIRECT LABOR COST | C13: -44502 | D13: -53652 | E13: -72848 | F13: -68377 | G13: -73683 | H13: -73683 | I13: -73683 | J13: -73683 | K13: -73683 | L13: -73683 | M13: -73683 | N13: -73683 | O13: =+SUM(C13:N13) -> -828843 | Q13: =-884195 -> -884195 | S13: =+O13-Q13 -> 55352
B14: HEADCOUNT | O14: =+SUM(C14:N14) -> 0
B15: CONTRIBUTION MARGIN | C15: =C8+C10+C13 -> -19993 | D15: =D8+D10+D13 -> -53718 | E15: =E8+E10+E13 -> -46131 | F15: =F8+F10+F13 -> -57931 | G15: =G8+G10+G13 -> 32046 | H15: =H8+H10+H13 -> 44680 | I15: =I8+I10+I13 -> 56223 | J15: =J8+J10+J13 -> 81532 | ... O15: =O8+O10+O13 -> 209833 | Q15: =Q8+Q10+Q13 -> 232455 | S15: =+O15-Q15 -> -22622
B16: as % of Revenue | C16: =IFERROR(C15/C8,"na") -> -0.49246268 | D16: =IFERROR(D15/D8,"na") -> -1.1667934 | E16: =IFERROR(E15/E8,"na") -> -1.0926856 | F16: =IFERROR(F15/F8,"na") -> -2.1708386 | G16: =IFERROR(G15/G8,"na") -> 0.22792967 | H16: =IFERROR(H15/H8,"na") -> 0.29158781 | I16: =IFERROR(I15/I8,"na") -> 0.34121488 | J16: =IFERROR(J15/J8,"na") -> 0.42893067 | ... N16: =IFERROR(N15/N8,"na") -> 0.17097379 | O16: =IFERROR(O15/$O$8,"na") -> 0.14863357 | Q16: =IFERROR(Q15/Q8,"na") -> 0.15141182
B17: TOTAL OPERATING EXPENSES (OPEX) | C17: =+C19+C20 -> -24318 | D17: =+D19+D20 -> -38869 | E17: =+E19+E20 -> -26103 | F17: =+F19+F20 -> -33860 | G17: =+G19+G20 -> -68257 | H17: =+H19+H20 -> -84057 | I17: =+I19+I20 -> -41507 | J17: =+J19+J20 -> -21707 | ... O17: =+O19+O20 -> -1231236 | Q17: =-1297286 -> -1297286 | S17: =+O17-Q17 -> 66050
B18: as % of Revenue | C18: =IFERROR(C17/C8,"na") -> -0.59899502 | D18: =IFERROR(D17/D8,"na") -> -0.84426247 | E18: =IFERROR(E17/E8,"na") -> -0.61829078 | F18: =IFERROR(F17/F8,"na") -> -1.2688301 | G18: =IFERROR(G17/G8,"na") -> -0.48548323 | H18: =IFERROR(H17/H8,"na") -> -0.54856751 | I18: =IFERROR(I17/I8,"na") -> -0.25190413 | J18: =IFERROR(J17/J8,"na") -> -0.11419808 | ... N18: =IFERROR(N17/N8,"na") -> -0.55525317 | O18: =IFERROR(O17/$O$8,"na") -> -0.87213644 | Q18: =IFERROR(Q17/$Q$8,"na") -> -0.84499984
B19: MKT (agencias, paid, fees amazon,etc) | C19: -2892 | D19: -7991 | E19: -9978 | F19: -13371 | G19: -62500 | H19: -78300 | I19: -35750 | J19: -15950 | K19: -710450 | L19: -63250 | M19: -28750 | N19: -67080 | O19: =SUM(C19:N19) -> -1096262 | Q19: =+Q17*T19 -> -1155071.3 | S19: =+O19-Q19 -> 58809.282 | T19: =+O19/$O$17 -> 0.8903752
B20: Other OPEX | C20: -21426 | D20: -30878 | E20: -16125 | F20: -20489 | G20: -5757 | H20: -5757 | I20: -5757 | J20: -5757 | K20: -5757 | L20: -5757 | M20: -5757 | N20: -5757 | O20: =SUM(C20:N20) -> -134974 | Q20: =+Q17*T20 -> -142214.72 | S20: =+O20-Q20 -> 7240.718 | T20: =+O20/$O$17 -> 0.1096248
B21: EBITDA | C21: =C15+C17 -> -44311 | D21: =D15+D17 -> -92587 | E21: =E15+E17 -> -72234 | F21: =F15+F17 -> -91791 | G21: =G15+G17 -> -36211 | H21: =H15+H17 -> -39377 | I21: =I15+I17 -> 14716 | J21: =J15+J17 -> 59825 | ... O21: =O15+O17 -> -1021403 | Q21: =Q15+Q17 -> -1064831 | S21: =+O21-Q21 -> 43428
B22: as % of Revenue | C22: =IFERROR(C21/C8,"na") -> -1.0914577 | D22: =IFERROR(D21/D8,"na") -> -2.0110558 | E22: =IFERROR(E21/E8,"na") -> -1.7109764 | F22: =IFERROR(F21/F8,"na") -> -3.4396687 | G22: =IFERROR(G21/G8,"na") -> -0.25755356 | H22: =IFERROR(H21/H8,"na") -> -0.2569797 | I22: =IFERROR(I21/I8,"na") -> 0.089310749 | J22: =IFERROR(J21/J8,"na") -> 0.31473259 | ... O22: =IFERROR(O21/O8,"na") -> -0.72350287 | Q22: =IFERROR(Q21/Q8,"na") -> -0.69358801
B23: Amortizaciones | C23: =+#REF! -> #REF! | D23: =+#REF! -> #REF! | E23: =+#REF! -> #REF! | F23: =+#REF! -> #REF! | G23: =+#REF! -> #REF! | H23: =+#REF! -> #REF! | I23: =+#REF! -> #REF! | J23: =+#REF! -> #REF! | ... O23: =+#REF! -> #REF! | Q23: =+#REF! -> #REF! | S23: =+O23-Q23 -> #REF!
B24: EBIT | C24: =C21+C23 -> #REF! | D24: =D21+D23 -> #REF! | E24: =E21+E23 -> #REF! | F24: =F21+F23 -> #REF! | G24: =G21+G23 -> #REF! | H24: =H21+H23 -> #REF! | I24: =I21+I23 -> #REF! | J24: =J21+J23 -> #REF! | ... O24: =O21+O23 -> #REF! | Q24: =Q21+Q23 -> #REF! | S24: =+O24-Q24 -> #REF!
B25: as % of Revenue | C25: =IFERROR(C24/C8,"na") -> na | D25: =IFERROR(D24/D8,"na") -> na | E25: =IFERROR(E24/E8,"na") -> na | F25: =IFERROR(F24/F8,"na") -> na | G25: =IFERROR(G24/G8,"na") -> na | H25: =IFERROR(H24/H8,"na") -> na | I25: =IFERROR(I24/I8,"na") -> na | J25: =IFERROR(J24/J8,"na") -> na | ... O25: =IFERROR(O24/O8,"na") -> na | Q25: -0.60977489
B26: Restd. Financiero | S26: =+O26-Q26 -> 0
B27: Impuesto sociedades | Q27: 0 | S27: =+O27-Q27 -> 0
B28: NET INCOME | C28: =+C24+C26+C27 -> #REF! | D28: =+D24+D26+D27 -> #REF! | E28: =+E24+E26+E27 -> #REF! | F28: =+F24+F26+F27 -> #REF! | G28: =+G24+G26+G27 -> #REF! | H28: =+H24+H26+H27 -> #REF! | I28: =+I24+I26+I27 -> #REF! | J28: =+J24+J26+J27 -> #REF! | ... O28: =+O24+O26+O27 -> #REF! | Q28: =+Q24+Q26+Q27 -> #REF! | S28: =+O28-Q28 -> #REF!
C30: =+C4 -> ACTUAL | D30: =+D4 -> ACTUAL | E30: =+E4 -> ACTUAL | F30: =+F4 -> ACTUAL | G30: =+G4 -> FORECAST | H30: =+H4 -> FORECAST | I30: =+I4 -> FORECAST | J30: =+J4 -> FORECAST | ... N30: =+N4 -> FORECAST | Q30: BP
B31: Cash Flow | C31: 2026 | D31: 2026 | E31: 2026 | F31: 2026 | G31: 2026 | H31: 2026 | I31: 2026 | J31: 2026 | K31: 2026 | L31: 2026 | M31: 2026 | N31: 2026 | Q31: 2026
C32: Enero | D32: Febrero | E32: Marzo | F32: Abril | G32: Mayo | H32: Junio | I32: Julio | J32: Agosto | K32: Septiembre | L32: Octubre | M32: Noviembre | N32: Diciembre | Q32: Total
B33: CASH-INS | C33: =+SUM(C34:C36) -> 0 | D33: =+SUM(D34:D36) -> 0 | E33: =+SUM(E34:E36) -> 0 | Q33: =+#REF! -> #REF!
B34: Cash position BoP
B35: Revenues
B36: APORTACION K
B37: CASH-OUT | C37: =+SUM(C38:C41) -> 0 | D37: =+SUM(D38:D41) -> 0 | E37: =+SUM(E38:E41) -> 0 | F37: =+SUM(F38:F41) -> 0 | G37: =+SUM(G38:G41) -> 0 | H37: =+SUM(H38:H41) -> 0 | I37: =+SUM(I38:I41) -> 0 | J37: =+SUM(J38:J41) -> 0 | ... N37: =+SUM(N38:N41) -> 0 | Q37: =+#REF! -> #REF!
B38: COGS
B39: Direct Labor
B40: Total OPEX
B41: PROFIT SHARING
B42: CAPEX | C42: =+#REF! -> #REF! | D42: =+#REF! -> #REF! | E42: =+#REF! -> #REF! | Q42: =+#REF! -> #REF!
B43: TOTAL CASH-OUTS + CAPEX | C43: =+C37+C42 -> #REF! | D43: =+D37+D42 -> #REF! | E43: =+E37+E42 -> #REF! | F43: =+F37+F42 -> 0 | G43: =+G37+G42 -> 0 | H43: =+H37+H42 -> 0 | I43: =+I37+I42 -> 0 | J43: =+J37+J42 -> 0 | ... N43: =+N37+N42 -> 0 | Q43: =+Q37+Q42 -> #REF!
B44: Costes financieros
...

Sheet Miia 
B2: ACTUALS + FORECAST | C2: Miia
C4: ACTUAL | D4: ACTUAL | E4: ACTUAL | F4: ACTUAL | G4: ACTUAL | H4: FORECAST | I4: FORECAST | J4: FORECAST | K4: FORECAST | L4: FORECAST | M4: FORECAST | N4: FORECAST | O4: Actuals + Forecast | Q4: BP
B5: Cuenta de Resultados | C5: 2026 | D5: 2026 | E5: 2026 | F5: 2026 | G5: 2026 | H5: 2026 | I5: 2026 | J5: 2026 | K5: 2026 | L5: 2026 | M5: 2026 | N5: 2026 | O5: 2026 | Q5: 2026
C6: Enero | D6: Febrero | E6: Marzo | F6: Abril | G6: Mayo | H6: Junio | I6: Julio | J6: Agosto | K6: Septiembre | L6: Octubre | M6: Noviembre | N6: Diciembre | O6: Total | Q6: Total | S6: Dif | T6: Comentarios
B8: REVENUE | C8: =+'[1] P&L (act + Forecast)'!F$21 -> 4546 | D8: =+'[1] P&L (act + Forecast)'!G$21 -> 5080 | E8: =+'[1] P&L (act + Forecast)'!H$21 -> 10504 | F8: =+'[1] P&L (act + Forecast)'!I$21 -> 14327 | G8: =+'[1] P&L (act + Forecast)'!J$21 -> 11037 | H8: =+'[1] P&L (act + Forecast)'!K$21 -> 22498.084 | I8: =+'[1] P&L (act + Forecast)'!L$21 -> 23744.861 | J8: =+'[1] P&L (act + Forecast)'!M$21 -> 22939.39 | ... N8: =+'[1] P&L (act + Forecast)'!Q$21 -> 38649.996 | O8: =+SUM(C8:N8) -> 282976.37 | Q8: =+'[1] P&L (act + Forecast)'!$T$21 -> 502554.1 | S8: =+O8-Q8 -> -219577.73 | T8: No hay ventas de equipos todo el modelo es suscripción
B9: % Growth | C9: =IFERROR((C8/B8)-1,"na") -> na | D9: =IFERROR((D8/C8)-1,"na") -> 0.1174659 | E9: =IFERROR((E8/D8)-1,"na") -> 1.0677165 | F9: =IFERROR((F8/E8)-1,"na") -> 0.36395659 | G9: =IFERROR((G8/F8)-1,"na") -> -0.22963635 | H9: =IFERROR((H8/G8)-1,"na") -> 1.0384239 | I9: =IFERROR((I8/H8)-1,"na") -> 0.05541703 | J9: =IFERROR((J8/I8)-1,"na") -> -0.033921921 | ... N9: =IFERROR((N8/M8)-1,"na") -> 0.079779162
B10: COGS | C10: =+'[1] P&L (act + Forecast)'!F$23 -> -4242 | D10: =+'[1] P&L (act + Forecast)'!G$23 -> -5207 | E10: =+'[1] P&L (act + Forecast)'!H$23 -> -12412 | F10: =+'[1] P&L (act + Forecast)'!I$23 -> -11770 | G10: =+'[1] P&L (act + Forecast)'!J$23 -> -9859 | H10: =+'[1] P&L (act + Forecast)'!K$23 -> -16050.381 | I10: =+'[1] P&L (act + Forecast)'!L$23 -> -15088.982 | J10: =+'[1] P&L (act + Forecast)'!M$23 -> -11548.256 | ... N10: =+'[1] P&L (act + Forecast)'!Q$23 -> -22451.406 | O10: =+SUM(C10:N10) -> -187473.69 | Q10: =+'[1] P&L (act + Forecast)'!$T$23 -> -246109.02 | S10: =+O10-Q10 -> 58635.326
B11: GROSS MARGIN | C11: =C8+C10 -> 304 | D11: =D8+D10 -> -127 | E11: =E8+E10 -> -1908 | F11: =F8+F10 -> 2557 | G11: =G8+G10 -> 1178 | H11: =H8+H10 -> 6447.7037 | I11: =I8+I10 -> 8655.8792 | J11: =J8+J10 -> 11391.134 | ... O11: =O8+O10 -> 95502.672 | Q11: =Q8+Q10 -> 256445.08 | S11: =+O11-Q11 -> -160942.4
B12: as % of Revenue | C12: =IFERROR(C11/C8,"na") -> 0.066871975 | D12: =IFERROR(D11/D8,"na") -> -0.025 | E12: =IFERROR(E11/E8,"na") -> -0.18164509 | F12: =IFERROR(F11/F8,"na") -> 0.17847421 | G12: =IFERROR(G11/G8,"na") -> 0.1067319 | H12: =IFERROR(H11/H8,"na") -> 0.28658901 | I12: =IFERROR(I11/I8,"na") -> 0.36453694 | J12: =IFERROR(J11/J8,"na") -> 0.49657529 | ... O12: =IFERROR(O11/O8,"na") -> 0.33749346 | Q12: =IFERROR(Q11/Q8,"na") -> 0.51028352
B13: DIRECT LABOR COST | C13: =+'[1] P&L (act + Forecast)'!F$30 -> -11629.333 | D13: =+'[1] P&L (act + Forecast)'!G$30 -> -21046.333 | E13: =+'[1] P&L (act + Forecast)'!H$30 -> -16668.333 | F13: =+'[1] P&L (act + Forecast)'!I$30 -> -16708 | G13: =+'[1] P&L (act + Forecast)'!J$30 -> -12802 | H13: =+'[1] P&L (act + Forecast)'!K$30 -> -22296.769 | I13: =+'[1] P&L (act + Forecast)'!L$30 -> -22045.654 | J13: =+'[1] P&L (act + Forecast)'!M$30 -> -19928.567 | ... N13: =+'[1] P&L (act + Forecast)'!Q$30 -> -24609.781 | O13: =+SUM(C13:N13) -> -242800.29 | Q13: =+'[1] P&L (act + Forecast)'!$T$30 -> -277070.48 | S13: =+O13-Q13 -> 34270.184
B14: HEADCOUNT | O14: =+SUM(C14:N14) -> 0
B15: CONTRIBUTION MARGIN | C15: =C8+C10+C13 -> -11325.333 | D15: =D8+D10+D13 -> -21173.333 | E15: =E8+E10+E13 -> -18576.333 | F15: =F8+F10+F13 -> -14151 | G15: =G8+G10+G13 -> -11624 | H15: =H8+H10+H13 -> -15849.065 | I15: =I8+I10+I13 -> -13389.774 | J15: =J8+J10+J13 -> -8537.4324 | ... O15: =O8+O10+O13 -> -147297.62 | Q15: =Q8+Q10+Q13 -> -20625.404 | S15: =+O15-Q15 -> -126672.22
B16: as % of Revenue | C16: =IFERROR(C15/C8,"na") -> -2.4912744 | D16: =IFERROR(D15/D8,"na") -> -4.167979 | E16: =IFERROR(E15/E8,"na") -> -1.7685009 | F16: =IFERROR(F15/F8,"na") -> -0.9877155 | G16: =IFERROR(G15/G8,"na") -> -1.0531847 | H16: =IFERROR(H15/H8,"na") -> -0.70446286 | I16: =IFERROR(I15/I8,"na") -> -0.56390199 | J16: =IFERROR(J15/J8,"na") -> -0.37217347 | ... N16: =IFERROR(N15/N8,"na") -> -0.21762464 | O16: =IFERROR(O15/$O$8,"na") -> -0.52052977 | Q16: =IFERROR(Q15/Q8,"na") -> -0.041041162
B17: TOTAL OPERATING EXPENSES (OPEX) | C17: =+C19+C20 -> -9138 | D17: =+D19+D20 -> -10154 | E17: =+E19+E20 -> -16627 | F17: =+F19+F20 -> -18780 | G17: =+G19+G20 -> -26073 | H17: =+H19+H20 -> -21895.75 | I17: =+I19+I20 -> -21895.75 | J17: =+J19+J20 -> -21755.7 | ... O17: =+O19+O20 -> -240565.22 | Q17: =+Q19+Q20 -> -243449.52 | S17: =+O17-Q17 -> 2884.2972
B18: as % of Revenue | C18: =IFERROR(C17/C8,"na") -> -2.0101188 | D18: =IFERROR(D17/D8,"na") -> -1.9988189 | E18: =IFERROR(E17/E8,"na") -> -1.5829208 | F18: =IFERROR(F17/F8,"na") -> -1.3108118 | G18: =IFERROR(G17/G8,"na") -> -2.3623267 | H18: =IFERROR(H17/H8,"na") -> -0.97322731 | I18: =IFERROR(I17/I8,"na") -> -0.92212583 | J18: =IFERROR(J17/J8,"na") -> -0.94839924 | ... N18: =IFERROR(N17/N8,"na") -> -0.59782025 | O18: =IFERROR(O17/$O$8,"na") -> -0.85012478 | Q18: =IFERROR(Q17/$O$8,"na") -> -0.86031749
B19: MKT (agencias, paid, fees amazon,etc) | C19: =+SUM('[1] P&L (act + Forecast)'!F45:F49) -> -7172 | D19: =+SUM('[1] P&L (act + Forecast)'!G45:G49) -> -8431 | E19: =+SUM('[1] P&L (act + Forecast)'!H45:H49) -> -14570 | F19: =+SUM('[1] P&L (act + Forecast)'!I45:I49) -> -17219 | G19: =+SUM('[1] P&L (act + Forecast)'!J45:J49) -> -21426 | H19: =+SUM('[1] P&L (act + Forecast)'!K45:K49) -> -19419.1 | I19: =+SUM('[1] P&L (act + Forecast)'!L45:L49) -> -19419.1 | J19: =+SUM('[1] P&L (act + Forecast)'!M45:M49) -> -15679.05 | ... N19: =+SUM('[1] P&L (act + Forecast)'!Q45:Q49) -> -19919.1 | O19: =+SUM(C19:N19) -> -204807.67 | Q19: =+'[1] P&L (act + Forecast)'!$T$45+'[1] P&L (act + Forecast)'!$T$46+'[1] P&L (act + Forecast)'!$T$48+'[1] P&L (act + Forecast)'!$T$49 -> -199412.31 | S19: =+O19-Q19 -> -5395.3628 | T19: Incluye comisiones de un externo (Sergi)
B20: Other OPEX | C20: =+'[1] P&L (act + Forecast)'!F$50 -> -1966 | D20: =+'[1] P&L (act + Forecast)'!G$50 -> -1723 | E20: =+'[1] P&L (act + Forecast)'!H$50 -> -2057 | F20: =+'[1] P&L (act + Forecast)'!I$50 -> -1561 | G20: =+'[1] P&L (act + Forecast)'!J$50 -> -4647 | H20: =+'[1] P&L (act + Forecast)'!K$50 -> -2476.65 | I20: =+'[1] P&L (act + Forecast)'!L$50 -> -2476.65 | J20: =+'[1] P&L (act + Forecast)'!M$50 -> -6076.65 | ... N20: =+'[1] P&L (act + Forecast)'!Q$50 -> -3186.65 | O20: =+SUM(C20:N20) -> -35757.55 | Q20: =+'[1] P&L (act + Forecast)'!$T$50 -> -44037.21 | S20: =+O20-Q20 -> 8279.66
B21: EBITDA | C21: =C15+C17 -> -20463.333 | D21: =D15+D17 -> -31327.333 | E21: =E15+E17 -> -35203.333 | F21: =F15+F17 -> -32931 | G21: =G15+G17 -> -37697 | H21: =H15+H17 -> -37744.815 | I21: =I15+I17 -> -35285.524 | J21: =J15+J17 -> -30293.132 | ... O21: =O15+O17 -> -387862.84 | Q21: =Q15+Q17 -> -264074.92 | S21: =+O21-Q21 -> -123787.92
B22: as % of Revenue | C22: =IFERROR(C21/C8,"na") -> -4.5013932 | D22: =IFERROR(D21/D8,"na") -> -6.1667979 | E22: =IFERROR(E21/E8,"na") -> -3.3514217 | F22: =IFERROR(F21/F8,"na") -> -2.2985273 | G22: =IFERROR(G21/G8,"na") -> -3.4155115 | H22: =IFERROR(H21/H8,"na") -> -1.6776902 | I22: =IFERROR(I21/I8,"na") -> -1.4860278 | J22: =IFERROR(J21/J8,"na") -> -1.3205727 | ... O22: =IFERROR(O21/O8,"na") -> -1.3706546 | Q22: =IFERROR(Q21/Q8,"na") -> -0.52546566
B23: Amortizaciones | C23: =+'[1] P&L (act + Forecast)'!F60 -> -1958 | D23: =+'[1] P&L (act + Forecast)'!G60 -> -1829 | E23: =+'[1] P&L (act + Forecast)'!H60 -> -2683 | F23: =+'[1] P&L (act + Forecast)'!I60 -> -2744 | G23: =+'[1] P&L (act + Forecast)'!J60 -> -2987 | H23: =+'[1] P&L (act + Forecast)'!K60 -> -2802.5627 | I23: =+'[1] P&L (act + Forecast)'!L60 -> -3216.1835 | J23: =+'[1] P&L (act + Forecast)'!M60 -> -3340.5024 | ... N23: =+'[1] P&L (act + Forecast)'!Q60 -> -5416.019 | O23: =+SUM(C23:N23) -> -40762.828 | Q23: =+'[1] P&L (act + Forecast)'!$T$60 -> -42369.945 | S23: =+O23-Q23 -> 1607.1174
B24: EBIT | C24: =C21+C23 -> -22421.333 | D24: =D21+D23 -> -33156.333 | E24: =E21+E23 -> -37886.333 | F24: =F21+F23 -> -35675 | G24: =G21+G23 -> -40684 | H24: =H21+H23 -> -40547.378 | I24: =I21+I23 -> -38501.708 | J24: =J21+J23 -> -33633.635 | ... O24: =O21+O23 -> -428625.67 | Q24: =Q21+Q23 -> -306444.87 | S24: =+O24-Q24 -> -122180.8
B25: as % of Revenue | C25: =IFERROR(C24/C8,"na") -> -4.9321015 | D25: =IFERROR(D24/D8,"na") -> -6.5268373 | E25: =IFERROR(E24/E8,"na") -> -3.6068482 | F25: =IFERROR(F24/F8,"na") -> -2.4900537 | G25: =IFERROR(G24/G8,"na") -> -3.6861466 | H25: =IFERROR(H24/H8,"na") -> -1.8022591 | I25: =IFERROR(I24/I8,"na") -> -1.6214754 | J25: =IFERROR(J24/J8,"na") -> -1.4661957 | ... O25: =IFERROR(O24/O8,"na") -> -1.5147048 | Q25: -0.60977489
B26: Restd. Financiero | S26: =+O26-Q26 -> 0
B27: Impuesto sociedades | Q27: 0 | S27: =+O27-Q27 -> 0
B28: NET INCOME | C28: =+C24+C26+C27 -> -22421.333 | D28: =+D24+D26+D27 -> -33156.333 | E28: =+E24+E26+E27 -> -37886.333 | F28: =+F24+F26+F27 -> -35675 | G28: =+G24+G26+G27 -> -40684 | H28: =+H24+H26+H27 -> -40547.378 | I28: =+I24+I26+I27 -> -38501.708 | J28: =+J24+J26+J27 -> -33633.635 | ... O28: =+O24+O26+O27 -> -428625.67 | Q28: =+Q24+Q26+Q27 -> -306444.87 | S28: =+O28-Q28 -> -122180.8
C30: =+C4 -> ACTUAL | D30: =+D4 -> ACTUAL | E30: =+E4 -> ACTUAL | F30: =+F4 -> ACTUAL | G30: =+G4 -> ACTUAL | H30: =+H4 -> FORECAST | I30: =+I4 -> FORECAST | J30: =+J4 -> FORECAST | ... N30: =+N4 -> FORECAST | Q30: BP
B31: Cash Flow | C31: 2026 | D31: 2026 | E31: 2026 | F31: 2026 | G31: 2026 | H31: 2026 | I31: 2026 | J31: 2026 | K31: 2026 | L31: 2026 | M31: 2026 | N31: 2026 | Q31: 2026
C32: Enero | D32: Febrero | E32: Marzo | F32: Abril | G32: Mayo | H32: Junio | I32: Julio | J32: Agosto | K32: Septiembre | L32: Octubre | M32: Noviembre | N32: Diciembre | Q32: Total
B33: CASH-INS | C33: =+SUM(C34:C36) -> 175813 | D33: =+SUM(D34:D36) -> 53836.59 | E33: =+SUM(E34:E36) -> 283142.59 | F33: =+SUM(F34:F36) -> 157978.59 | G33: =+SUM(G34:G36) -> 83131.59 | H33: =+SUM(H34:H36) -> 0 | I33: =+SUM(I34:I36) -> 0 | J33: =+SUM(J34:J36) -> 0 | ... N33: =+SUM(N34:N36) -> 0 | Q33: =+'[1] P&L (act + Forecast)'!$T$73 -> 502554.1
B34: Cash position BoP | C34: =+'[1] P&L (act + Forecast)'!$B$95 -> 72344 | D34: =+C45 -> 49849.59 | E34: =+D45 -> 27868.59 | F34: =+E45 -> 149665.59 | G34: =+F45 -> 71242.59
B35: Revenues | C35: =+SUM('[1] P&L (act + Forecast)'!F74:F76) -> 3469 | D35: =+SUM('[1] P&L (act + Forecast)'!G74:G76) -> 3987 | E35: =+SUM('[1] P&L (act + Forecast)'!H74:H76) -> 5274 | F35: =+SUM('[1] P&L (act + Forecast)'!I74:I76) -> 8313 | G35: =+SUM('[1] P&L (act + Forecast)'!J74:J76) -> 11889
B36: APORTACION K | C36: =+'[1] P&L (act + Forecast)'!F77 -> 100000 | D36: =+'[1] P&L (act + Forecast)'!G77 -> 0 | E36: =+'[1] P&L (act + Forecast)'!H77 -> 250000 | F36: =+'[1] P&L (act + Forecast)'!I77 -> 0 | G36: =+'[1] P&L (act + Forecast)'!J77 -> 0
B37: CASH-OUT | C37: =+SUM(C38:C41) -> -37074 | D37: =+SUM(D38:D41) -> -17710 | E37: =+SUM(E38:E41) -> -41810 | F37: =+SUM(F38:F41) -> -60862 | G37: =+SUM(G38:G41) -> -48273 | H37: =+SUM(H38:H41) -> 0 | I37: =+SUM(I38:I41) -> 0 | J37: =+SUM(J38:J41) -> 0 | ... N37: =+SUM(N38:N41) -> 0 | Q37: =+'[1] P&L (act + Forecast)'!$T$78 -> -766629.02
B38: COGS | C38: =+'[1] P&L (act + Forecast)'!F79 -> -8526 | D38: =+'[1] P&L (act + Forecast)'!G79 -> -4617 | E38: =+'[1] P&L (act + Forecast)'!H79 -> -10614 | F38: =+'[1] P&L (act + Forecast)'!I79 -> -17675 | G38: =+'[1] P&L (act + Forecast)'!J79 -> -23128 | Q38: =+'[1] P&L (act + Forecast)'!T79 -> -246109.02
B39: Direct Labor | C39: =+'[1] P&L (act + Forecast)'!F80 -> -15966 | D39: =+'[1] P&L (act + Forecast)'!G80 -> -2962 | E39: =+'[1] P&L (act + Forecast)'!H80 -> -23776 | F39: =+'[1] P&L (act + Forecast)'!I80 -> -25406 | G39: =+'[1] P&L (act + Forecast)'!J80 -> -11297 | Q39: =+'[1] P&L (act + Forecast)'!T80 -> -277070.48
B40: Total OPEX | C40: =+'[1] P&L (act + Forecast)'!F81 -> -12582 | D40: =+'[1] P&L (act + Forecast)'!G81 -> -10131 | E40: =+'[1] P&L (act + Forecast)'!H81 -> -7420 | F40: =+'[1] P&L (act + Forecast)'!I81 -> -17781 | G40: =+'[1] P&L (act + Forecast)'!J81 -> -13848 | Q40: =+'[1] P&L (act + Forecast)'!T81 -> -243449.52
B41: PROFIT SHARING | C41: 0 | D41: 0 | E41: 0 | F41: 0 | G41: 0 | Q41: =+'[1] P&L (act + Forecast)'!T82 -> 0
B42: CAPEX | C42: =+'[1] P&L (act + Forecast)'!F83 -> -85729 | D42: =+'[1] P&L (act + Forecast)'!G83 -> -8258 | E42: =+'[1] P&L (act + Forecast)'!H83 -> -91667 | F42: =+'[1] P&L (act + Forecast)'!I83 -> -25874 | G42: =+'[1] P&L (act + Forecast)'!J83 -> -17268 | Q42: =+'[1] P&L (act + Forecast)'!$T$83 -> -423884.25
B43: TOTAL CASH-OUTS + CAPEX | C43: =+C37+C42 -> -122803 | D43: =+D37+D42 -> -25968 | E43: =+E37+E42 -> -133477 | F43: =+F37+F42 -> -86736 | G43: =+G37+G42 -> -65541 | H43: =+H37+H42 -> 0 | I43: =+I37+I42 -> 0 | J43: =+J37+J42 -> 0 | ... N43: =+N37+N42 -> 0 | Q43: =+Q37+Q42 -> -1190513.3
B44: Costes financieros | C44: =+'[1] P&L (act + Forecast)'!F89 -> -3160.41 | D44: =+'[1] P&L (act + Forecast)'!G89 -> 0 | E44: =+'[1] P&L (act + Forecast)'!H89 -> 0 | F44: =+'[1] P&L (act + Forecast)'!I89 -> 0 | G44: =+'[1] P&L (act + Forecast)'!J89 -> 0
...

Sheet CONSOLIDADO
B2: ACTUAL + FORECAST | C2: [Company Name]
C4: ACTUAL | D4: ACTUAL | E4: ACTUAL | F4: ACTUAL | G4: ACTUAL | H4: FORECAST | I4: FORECAST | J4: FORECAST | K4: FORECAST | L4: FORECAST | M4: FORECAST | N4: FORECAST | O4: Actual+Forecast | Q4: BP
B5: Cuenta de Resultados | C5: 2026 | D5: 2026 | E5: 2026 | F5: 2026 | G5: 2026 | H5: 2026 | I5: 2026 | J5: 2026 | K5: 2026 | L5: 2026 | M5: 2026 | N5: 2026 | O5: 2026 | Q5: 2026
C6: Enero | D6: Febrero | E6: Marzo | F6: Abril | G6: Mayo | H6: Junio | I6: Julio | J6: Agosto | K6: Septiembre | L6: Octubre | M6: Noviembre | N6: Diciembre | O6: Total | Q6: Total | S6: Dif | T6: Comentarios | U6: Check
